<?xml version="1.0"?>
  <robot name="cube_scene">
    <link name="base_link"/>

    <link name="table">
      <visual>
        <geometry>
          <box size="0.55 1.0 0.3" />
        </geometry>
        <origin rpy="0 0 0" xyz="0 0 0" />

<material name = "">
          <color rgba="0.9 0.9 0.9 1.0"/>
</material>

      </visual>

      <collision>
        <geometry>
          <box size="0.55 1.0 0.3" />
        </geometry>
        <origin rpy="0 0 0" xyz="0 0 0" />       
       </collision>
    </link>

  

    <link name="cone2">
      <visual>
        <geometry>
          <mesh filename="file:///home/serboba/Desktop/blenderFLEX/cone.dae" scale="0.052 0.052 0.052" />
        </geometry>
        <origin rpy="0 0 0" xyz="0 0 0" />
      <material name = "">
          <color rgba="1.0 0.5 0.0 1.0"/>
      </material>
      
      </visual>
      
      <collision>     
        <geometry>
          <mesh filename="file:///home/serboba/Desktop/blenderFLEX/cone.dae" scale="0.052 0.052 0.052"/>
        </geometry>
        <origin rpy="0 0 0" xyz="0 0 0" />  
       </collision>

    </link>

    <link name="cube1">
      <visual>
        <geometry>
          <box size="0.1 0.1 0.1"/>
        </geometry>
        <origin rpy="0 0 0" xyz="0 0 0" />
      <material name = "">
          <color rgba="0.0 0.8 0.0 1.0"/>
      </material>
      </visual>
      <collision>
        <geometry>
          <box size="0.1 0.1 0.1"/>
        </geometry>
        <origin rpy="0 0 0" xyz="0 0 0" />       
       </collision>
    </link>

     <link name="door1">
      <visual>
        <geometry>
          <box size="0.03 0.146 0.173"/>
        </geometry>
        <origin rpy="0 0 0" xyz="0.0 0 0" />
      </visual>
      <collision>
        <geometry>  
          <box size="0.03 0.146 0.173"/>
        </geometry>
        <origin rpy="0 0 0" xyz="0 0 0" />       
       </collision>
    </link>


     <link name="door2">
      <visual>
      <origin rpy="0 0 0" xyz="0 0 0" />
        <geometry>
          <box size="0.03 0.146 0.173"/>
        </geometry>
      </visual>
      <collision>       
        <geometry>  
          <box size="0.03 0.146 0.173"/>
        </geometry>
        <origin rpy="0 0 0" xyz="0 0 0" />
       </collision>
    </link>


<joint name="table_j" type="fixed">
    <origin rpy="0 0 0" xyz="0.75 -0.6 0.63" />
    <parent link="base_link" />
    <child link="table" />
    <axis xyz="0 1 0" />
  </joint>



<joint name="cube_joint" type="prismatic">
    <origin rpy="0 0 0" xyz="0.60 -0.2 0.84" />
    <parent link="base_link" />
    <child link="cube1" />
    <axis xyz="0 -1 0" />

  <limit lower="0" upper="1.0" effort="0.05" velocity="1.57"/>
  </joint>


    <joint name="door_joint1" type="prismatic">
        <origin rpy="0 0 1.57" xyz="0.6 -0.5 0.87"/>
        <parent link="base_link"/>
        <child link="door1"/>
        <axis xyz="0.0 -1.0 0.0"/>
        <limit lower="0" upper="0.4" effort="0.05" velocity="1.57"/>
    </joint>

    <joint name="door_joint2" type="prismatic">
        <origin rpy="0 0 1.57" xyz="0.6 -0.7 0.87"/>
        <parent link="base_link"/>
        <child link="door2"/>
        <axis xyz="0.0 -1.0 0.0"/>
        <limit lower="0" upper="0.4" effort="0.05" velocity="1.57"/>
    </joint>



 <joint name="cone_joint2" type="fixed">
    <origin rpy="0 0 0" xyz="0.75 -0.96 0.775" />
    <parent link="base_link" />
    <child link="cone2" />
    <axis xyz="0 1 0" />
  </joint>





</robot>