<?xml version="1.0"?>
    <robot name="myfirst">

  

    
      <link name="base_link1">
        <origin xyz="0.4 0.25 0.3"/>
        </link>



    <link name="door">
        <visual>
         <geometry>
             <box size="0.6 0.5 0.05"/>
         </geometry>   
         <origin rpy="0.0 1.57075 0.0" xyz="0.0 0.25 0.0"/>
        </visual>
     
       
    </link>

    <joint name="base_to_door" type="revolute">
        <parent link="base_link1"/>
        <child link="door"/>
        <origin xyz="0.4 -0.25 0.3"/>
        <axis xyz="0.0 0.0 1"/>
        <limit lower="-3.17" upper="0.43" effort="0.05" velocity="1.57"/>
    </joint>

    </robot>