<?xml version="1.0"?>
  <robot name="maze1">
    <link name="base_link"/>

    <link name="table">
      <visual>
        <geometry>
          <mesh filename="file:///home/serboba/Desktop/blenderFLEX/maze1.dae" scale = " 0.50 0.50 0.50"/>
        </geometry>
        <origin rpy="0 0 0" xyz="0 0 0" />

<material name = "">
  <color rgba="0.87450980392 0.87450980392 0.87058823529 1.0"/>
      </material>

      </visual>

      <collision>
        <geometry>
          <mesh filename="file:///home/serboba/Desktop/blenderFLEX/maze1.dae" scale = " 0.50 0.50 0.50"/>
        </geometry>
        <origin rpy="0 0 0" xyz="0 0 0" />       
       </collision>
    </link>

    <link name="cube">
      <visual>
        <geometry>
          <box size="0.1 0.1 0.1"/>
        </geometry>
        <origin rpy="0 0 0" xyz="0 0 0" />
      <material name = "">
          <color rgba="0.0 0.8 0.0 1.0"/>
      </material>
      </visual>
      <collision>
        <geometry>
          <box size="0.1 0.1 0.1"/>
        </geometry>
        <origin rpy="0 0 0" xyz="0 0 0" />       
       </collision>
    </link>


    <link name="cube2">
      <visual>
        <geometry>
          <box size="0.08 0.08 0.08"/>
        </geometry>
        <origin rpy="0 0 0" xyz="0 0 0" />
      <material name = "">
          <color rgba="0.0 0.8 0.0 0.4"/>
      </material>
      </visual>
    </link>



     <link name="door1">
      <visual>
        <geometry>
          <box size="0.03 0.5 0.173"/>
        </geometry>
        <origin rpy="0 0 0" xyz="0.0 0.25 0" />
        <material name = "">
          <color rgba="0.6901 0.2509 0.2509 1.0"/>
      </material>
      </visual>
      <collision>
        <geometry>  
          <box size="0.03 0.5 0.173"/>
        </geometry>
        <origin rpy="0 0 0" xyz="0.0 0.25 0" />       
       </collision>
    </link>


     <link name="door3">
      <visual>
      <origin rpy="0 0 0" xyz="0 0.225 0" />
        <geometry>
          <box size="0.03 0.45 0.173"/>
        </geometry>
             <material name = "">
          <color rgba="0.6901 0.2509 0.2509 1.0"/>
      </material>
      </visual>
      <collision>       
        <geometry>  
          <box size="0.03 0.45 0.173"/>
        </geometry>
        <origin rpy="0 0 0" xyz="0 0.225 0" />
       </collision>
    </link>


     <link name="door2">
      <visual>
      <origin rpy="0 0 0" xyz="0 -0.225 0" />
        <geometry>
          <box size="0.03 0.5 0.173"/>
        </geometry>
             <material name = "">
          <color rgba="0.6901 0.2509 0.2509 1.0"/>
      </material>
      </visual>
      <collision>       
        <geometry>  
          <box size="0.03 0.5 0.173"/>
        </geometry>
        <origin rpy="0 0 0" xyz="0 -0.225 0" />
       </collision>
    </link>

<link name ="cube_x"/>

<joint name="table_j" type="fixed">
    <origin rpy="0 0 0" xyz="0.75 -0.6 0.23" />
    <parent link="base_link" />
    <child link="table" />
    <axis xyz="0 1 0" />
  </joint>



<joint name="goal" type="fixed">
    <origin rpy="0 0 0" xyz="0.5 -0.25 0.75" />
    <parent link="base_link" />
    <child link="cube2" />
    <axis xyz="0 1 0" />
  </joint>


<joint name="cube_joint" type="prismatic">
    <origin rpy="0 0 0" xyz="0.50 -0.8 0.75" />
    <parent link="base_link" />
    <child link="cube_x" />
   <axis xyz="1 0 0" />
  <limit lower="-0.2" upper="0.7" effort="0.05" velocity="1.57"/>
  </joint>


<joint name="cube_joint2" type="prismatic">
    <origin rpy="0 0 0" xyz="0.0 0 0.0" />
    <parent link="cube_x" />
    <child link="cube" />
   <axis xyz="0 1 0" />
  <limit lower="0.0" upper="0.65" effort="0.05" velocity="1.57"/>
  </joint>


    <joint name="door_joint1" type="revolute">
        <origin rpy="0 0 0" xyz="0.75 -1.125 0.755"/>
        <parent link="base_link"/>
        <child link="door1"/>
        <axis xyz="0 0 1"/>
        <limit lower="-1.57" upper="1.57" effort="5" velocity="1.57"/>
    </joint>

 <joint name="door_joint2" type="revolute">
        <origin rpy="0 0 -1.57" xyz="1.25 -0.575 0.755"/>
        <parent link="base_link"/>
        <child link="door2"/>
        <axis xyz="0 0 1"/>
        <limit lower="-1.57" upper="1.57" effort="5" velocity="1.57"/>
    </joint>


    <joint name="door_joint3" type="revolute">
        <origin rpy="0 0 0" xyz="0.75 -0.525 0.755"/>
        <parent link="base_link"/>
        <child link="door3"/>
        <axis xyz="0.0 0.0 1"/>
        <limit lower="-1.57" upper="1.57" effort="5" velocity="1.57"/>
    </joint>

</robot>
