<?xml version="1.0"?>
  <robot name="maze2">
    <link name="base_link"/>

    <link name="table">
      <visual>
        <geometry>
          <mesh filename="file:///home/serboba/Desktop/blenderFLEX/table_maze3.dae" scale = " 0.750 0.750 0.750"/>
        </geometry>
        <origin rpy="0 0 0" xyz="0 0 0" />

<material name = "">
          <color rgba="0.87450980392 0.87450980392 0.87058823529 1.0"/>
      </material>

      </visual>
      <collision>
        <geometry>
          <mesh filename="file:///home/serboba/Desktop/blenderFLEX/table_maze3.dae" scale = " 0.750 0.750 0.750"/>
        </geometry>
        <origin rpy="0 0 0" xyz="0 0 0" />       
       </collision>
    </link>

    <link name="cube1">
      <visual>
        <geometry>
          <box size="0.1 0.1 0.1"/>
        </geometry>
        <origin rpy="0 0 0" xyz="0 0 0" />
      <material name = "">
          <color rgba="0.0 0.8 0.0 1.0"/>
      </material>
      </visual>
      <collision>
        <geometry>
          <box size="0.1 0.1 0.1"/>
        </geometry>
        <origin rpy="0 0 0" xyz="0 0 0" />       
       </collision>
    </link>


<link name ="cube_x"/>


     <link name="door1">
      <visual>
        <geometry>
          <box size="0.40 0.025 0.16"/>
        </geometry>
        <origin rpy="0 0 0" xyz="0.0 0.0 0" />
        <material name = "">
          <color rgba="0.91372549019 0.39215686274 0.39215686274 1.0"/>
        </material>
      </visual>
      <collision>
        <geometry>
          <box size="0.40 0.025 0.16"/>
        </geometry>
        <origin rpy="0 0 0" xyz="0.0 0.0 0" />
        </collision>
    </link>

     <link name="door2">
      <visual>
        <geometry>
          <box size="0.40 0.025 0.16"/>
        </geometry>
        <origin rpy="0 0 0" xyz="0.0 0.0 0" />
        <material name = "">
          <color rgba="0.91372549019 0.39215686274 0.39215686274 1.0"/>
        </material>
      </visual>
      <collision>
        <geometry>
          <box size="0.40 0.025 0.16"/>
        </geometry>
        <origin rpy="0 0 0" xyz="0.0 0.0 0" />
        </collision>
    </link>

     <link name="door3">
      <visual>
        <geometry>
          <box size="0.40 0.025 0.16"/>
        </geometry>
        <origin rpy="0 0 0" xyz="0.0 0.0 0" />
        <material name = "">
          <color rgba="0.91372549019 0.39215686274 0.39215686274 1.0"/>
        </material>
      </visual>
      <collision>
        <geometry>
          <box size="0.40 0.025 0.16"/>
        </geometry>
        <origin rpy="0 0 0" xyz="0.0 0.0 0" />
        </collision>
    </link>

         <link name="door4">
      <visual>
        <geometry>
          <box size="0.40 0.025 0.16"/>
        </geometry>
        <origin rpy="0 0 0" xyz="0.0 0.0 0" />
        <material name = "">
          <color rgba="0.91372549019 0.39215686274 0.39215686274 1.0"/>
        </material>
      </visual>
      <collision>
        <geometry>
          <box size="0.40 0.025 0.16"/>
        </geometry>
        <origin rpy="0 0 0" xyz="0.0 0.0 0" />
        </collision>
    </link>


<joint name="table_j" type="fixed">
    <origin rpy="0 0 0" xyz="0.9 -0.4 0.73" />
    <parent link="base_link" />
    <child link="table" />
    <axis xyz="0 1 0" />
  </joint>



<joint name="cube_joint" type="prismatic">
    <origin rpy="0 0 0" xyz="0.40 -0.9 0.86" />
    <parent link="base_link" />
    <child link="cube_x" />
   <axis xyz="1 0 0" />
  <limit lower="-0.17" upper="1.18" effort="0.05" velocity="1.57"/>
  </joint>


<joint name="cube_joint2" type="prismatic">
    <origin rpy="0 0 0" xyz="0.0 0 0.0" />
    <parent link="cube_x" />
    <child link="cube1" />
   <axis xyz="0 1 0" />
  <limit lower="-0.1" upper="1.11" effort="0.05" velocity="1.57"/>
  </joint>


    <joint name="door_joint1" type="prismatic">
        <origin rpy="0 0 0" xyz="0.39 -0.634 0.86"/>
        <parent link="base_link"/>
        <child link="door1"/>
        <axis xyz="1 0 0"/>
        <limit lower="0" upper="1.02" effort="5" velocity="1.57"/>
    </joint>

 <joint name="door_joint2" type="prismatic">
    <origin rpy="0 0 0" xyz="0.39 -0.166 0.86"/>
        <parent link="base_link"/>
        <child link="door2"/>
        <axis xyz="1 0 0"/>
        <limit lower="0" upper="1.02" effort="5" velocity="1.57"/>
  </joint>


    <joint name="door_joint3" type="prismatic">
        <origin rpy="0 0 0" xyz="1.41 -0.634 0.86"/>
        <parent link="base_link"/>
        <child link="door3"/>
        <axis xyz="-1 0 0"/>
        <limit lower="0" upper="1.02" effort="5" velocity="1.57"/>
    </joint>

 <joint name="door_joint4" type="prismatic">
    <origin rpy="0 0 0" xyz="1.41 -0.166 0.86"/>
        <parent link="base_link"/>
        <child link="door4"/>
        <axis xyz="-1 0 0"/>
        <limit lower="0" upper="1.02" effort="5" velocity="1.57"/>
  </joint>


</robot>
